# ES4X Asynchronous helpers

Imagine the following piece of code:

```js
function one() {
   two(function(err) {
     if(err) throw err;
     console.log("two finished");
   });
}

function two(callback) {
  setTimeout(function () { 
    three(function(err) {
      if(err) return callback(err);
      console.log("three finished");
      callback();
    });
  }, 0);
}

function three(callback)
{
  setTimeout(function () { 
    four(function(err) {
      if(err) return callback(err);
      console.log("four finished");
      callback();
    });
  }, 0);
}

function four(callback) {
  setTimeout(function(){
    callback(new Error());
  }, 0);
}

one();
```

If you run this code you will see that your error has the following trace:

```
Error
    at Timer.callback (example.js:34)
```

Which is not very useful if you need to debug. 

In order to ease this there is a bundled module with ES4X that will stitch your
exceptions together, every time you would handle a callback instead of passing the
error directly you wrap it with a helper function.

```js
var asyncError = require('async-error');
var fs = vertx.fileSystem();

function one() {
  two(function (err) {
    if (err) {
      console.trace(err);
      test.complete();
      return;
    }

    console.log("two finished");
    should.fail("Should not reach here");
  });
}

function two(callback) {
  setTimeout(function () {
    three(function (err) {
      if (err) {
        setTimeout(function () {
          callback(asyncError(err));
        }, 0);
        return;
      }

      console.log("three finished");
      callback();
    });
  }, 0);
}

function three(callback) {
  setTimeout(function () {
    four(function (err) {
      if (err) {
        setTimeout(function () {
          callback(asyncError(err));
        }, 0);
        return;
      }

      console.log("four finished");
      callback();
    });
  }, 0);
}

function four(callback) {
  setTimeout(function () {
    fs.readFile("durpa/durp.txt", function (ar) {
      if (ar.failed()) {
        callback(asyncError(ar));
      }
    });
  }, 0);
}

one();
```

Knowing that the file `durpa/durp.txt` doesn't exist, now you would see:

```
Error: File not found!
    at stacktraces/jserror.js:24:20
    at stacktraces/jserror.js:40:20
    at stacktraces/jserror.js:53:14
    at stacktraces/jserror.js:53:25
    at classpath:io/reactiverse/es4x/polyfill/global.js:25:18
```

If the error that is being propagated in a JS `Error` object or:

```
io.vertx.core.file.FileSystemException: java.nio.file.NoSuchFileException: durpa/durp.txt
	at <async>.<anonymous> (stacktraces/index.js:30)
	at <async>.<anonymous> (stacktraces/index.js:46)
	at <async>.<anonymous> (stacktraces/index.js:61)
	at io.vertx.core.file.impl.FileSystemImpl$13.perform(FileSystemImpl.java:740)
	at io.vertx.core.file.impl.FileSystemImpl$13.perform(FileSystemImpl.java:732)
	at io.vertx.core.impl.ContextImpl.lambda$executeBlocking$1(ContextImpl.java:275)
	at io.vertx.core.impl.TaskQueue.run(TaskQueue.java:76)
	at java.util.concurrent.ThreadPoolExecutor.runWorker(ThreadPoolExecutor.java:1149)
	at java.util.concurrent.ThreadPoolExecutor$Worker.run(ThreadPoolExecutor.java:624)
	at io.netty.util.concurrent.FastThreadLocalRunnable.run(FastThreadLocalRunnable.java:30)
	at java.lang.Thread.run(Thread.java:748)
Caused by: java.nio.file.NoSuchFileException: durpa/durp.txt
	at sun.nio.fs.UnixException.translateToIOException(UnixException.java:86)
	at sun.nio.fs.UnixException.rethrowAsIOException(UnixException.java:102)
	at sun.nio.fs.UnixException.rethrowAsIOException(UnixException.java:107)
	at sun.nio.fs.UnixFileSystemProvider.newByteChannel(UnixFileSystemProvider.java:214)
	at java.nio.file.Files.newByteChannel(Files.java:361)
	at java.nio.file.Files.newByteChannel(Files.java:407)
	at java.nio.file.Files.readAllBytes(Files.java:3152)
	at io.vertx.core.file.impl.FileSystemImpl$13.perform(FileSystemImpl.java:736)
	... 7 more
```

If the error is a Java Throwable.
